output/04.txt
time symbol vwap
4:00:00 A 73.83
4:00:00 AA 53.67
4:00:00 AAAP 81.96
4:00:00 AABA 77.78
4:00:00 AADR 61.99
4:00:00 AAL 52.64
4:00:00 AAN 41.68
4:00:00 AAOI 32.39
4:00:00 AAON 36.02
4:00:00 AAP 121.66
4:00:00 AAPL 165.51
4:00:00 AAT 34.91
4:00:00 AAU 0.88
4:00:00 AAWW 58.23
4:00:00 AAXJ 81.35
4:00:00 AAXN 27.28
4:00:00 ABAX 74.77
4:00:00 ABB 28.08
4:00:00 ABBV 119.42
4:00:00 ABC 100.98
4:00:00 ABCB 55.04
4:00:00 ABCD 7.06
4:00:00 ABEO 15.25
4:00:00 ABEV 6.82
4:00:00 ABG 74.65
4:00:00 ABIO 1.78
4:00:00 ABLX 54.36
4:00:00 ABM 38.41
4:00:00 ABMD 228.74
4:00:00 ABR 8.32
4:00:00 ABT 62.61
4:00:00 ABTX 40.75
4:00:00 ABUS 5.12
4:00:00 ABX 14.47
4:00:00 ACAD 31.08
4:00:00 ACBI 17.32
4:00:00 ACC 38.48
4:00:00 ACET 11.64
4:00:00 ACFC 10.54
4:00:00 ACGL 91.84
4:00:00 ACGLO 24.79
4:00:00 ACGLP 23.43
4:00:00 ACH 17.6
4:00:00 ACHC 34.33
4:00:00 ACHN 2.76
4:00:00 ACIA 35.08
4:00:00 ACIU 13.43
4:00:00 ACIW 23.02
4:00:00 ACLS 26.1
4:00:00 ACM 38.79
4:00:00 ACMR 5.4
4:00:00 ACN 160.57
4:00:00 ACOR 26.88
4:00:00 ACP 14.46
4:00:00 ACRE 12.84
4:00:00 ACRS 23.05
4:00:00 ACST 1.17
4:00:00 ACTG 3.95
4:00:00 ACU 24.04
4:00:00 ACV 22.48
4:00:00 ACWI 76.37
4:00:00 ACXM 27.4
4:00:00 ADAP 9.0
4:00:00 ADBE 196.5
4:00:00 ADC 48.02
4:00:00 ADES 8.12
4:00:00 ADI 92.5
4:00:00 ADM 42.63
4:00:00 ADMA 3.91
4:00:00 ADMP 3.68
4:00:00 ADMS 37.9
4:00:00 ADNT 66.38
4:00:00 ADOM 1.68
4:00:00 ADP 120.87
4:00:00 ADRE 47.42
4:00:00 ADRO 6.72
4:00:00 ADS 255.47
4:00:00 ADSK 115.65
4:00:00 ADSW 24.19
4:00:00 ADT 12.05
4:00:00 ADTN 16.11
4:00:00 ADUS 36.42
4:00:00 ADVM 7.29
4:00:00 ADXS 3.0
4:00:00 AEE 56.06
4:00:00 AEG 6.9
4:00:00 AEGN 25.51
4:00:00 AEIS 73.22
4:00:00 AEL 34.56
4:00:00 AEM 48.13
4:00:00 AEMD 1.62
4:00:00 AEO 18.29
4:00:00 AEP 68.24
4:00:00 AER 54.79
4:00:00 AERI 56.36
4:00:00 AES 11.73
4:00:00 AET 188.12
4:00:00 AETI 1.5
4:00:00 AEZS 2.32
4:00:00 AFAM 58.12
4:00:00 AFB 12.93
4:00:00 AFG 113.68
4:00:00 AFH 19.95
4:00:00 AFHBL 26.7
4:00:00 AFI 15.79
4:00:00 AFK 25.98
4:00:00 AFL 88.88
4:00:00 AFMD 1.32
4:00:00 AFSI 13.24
4:00:00 AG 6.4
4:00:00 AGCO 72.67
4:00:00 AGD 11.33
4:00:00 AGEN 3.65
4:00:00 AGFS 7.45
4:00:00 AGG 108.05
4:00:00 AGI 6.12
4:00:00 AGIO 79.15
4:00:00 AGLE 6.08
4:00:00 AGN 183.26
4:00:00 AGNC 19.08
4:00:00 AGO 36.16
4:00:00 AGR 47.96
4:00:00 AGRX 3.3
4:00:00 AGS 18.19
4:00:00 AGTC 5.35
4:00:00 AGX 43.95
4:00:00 AHC 5.0
4:00:00 AHGP 29.13
4:00:00 AHH 14.44
4:00:00 AHL 37.31
4:00:00 AHP 9.48
4:00:00 AHT-H 23.11
4:00:00 AHT-I 23.55
4:00:00 AI 10.79
4:00:00 AIA 71.04
4:00:00 AIEQ 27.52
4:00:00 AIG 63.96
4:00:00 AIG+ 21.96
4:00:00 AIMC 52.25
4:00:00 AIMT 35.12
4:00:00 AIN 62.96
4:00:00 AINV 5.76
4:00:00 AIR 40.2
4:00:00 AIRG 10.15
4:00:00 AIT 73.97
4:00:00 AIV 41.2
4:00:00 AIZ 93.69
4:00:00 AJG 69.84
4:00:00 AJRD 28.28
4:00:00 AJX 13.41
4:00:00 AKAM 66.64
4:00:00 AKAO 11.88
4:00:00 AKBA 15.36
4:00:00 AKCA 22.14
4:00:00 AKER 0.26
4:00:00 AKG 0.93
4:00:00 AKR 24.83
4:00:00 AKRX 32.12
4:00:00 AKS 6.12
4:00:00 AKTS 5.83
4:00:00 AL 49.62
4:00:00 ALB 112.67
4:00:00 ALBO 37.46
4:00:00 ALCO 27.15
4:00:00 ALDR 13.98
4:00:00 ALDW 16.76
4:00:00 ALDX 7.55
4:00:00 ALE 71.74
4:00:00 ALEX 27.5
4:00:00 ALG 118.02
4:00:00 ALGN 263.13
4:00:00 ALGT 160.05
4:00:00 ALIM 1.16
4:00:00 ALJJ 3.3
4:00:00 ALK 64.77
4:00:00 ALKS 58.45
4:00:00 ALL 98.65
4:00:00 ALLE 86.1
4:00:00 ALLT 4.96
4:00:00 ALLY 30.03
4:00:00 ALLY-A 25.93
4:00:00 ALNA 9.07
4:00:00 ALNY 130.44
4:00:00 ALOG 84.53
4:00:00 ALPN 11.6
4:00:00 ALRM 37.62
4:00:00 ALSN 44.25
4:00:00 ALTR 24.98
4:00:00 ALTY 15.28
4:00:00 ALV 147.19
4:00:00 ALXN 125.82
4:00:00 AM 31.22
4:00:00 AMAG 14.49
4:00:00 AMAT 53.86
4:00:00 AMBA 50.02
4:00:00 AMBC 16.53
4:00:00 AMC 12.75
4:00:00 AMCN 1.19
4:00:00 AMCX 53.67
4:00:00 AMD 13.14
4:00:00 AME 77.41
4:00:00 AMED 54.21
4:00:00 AMG 206.37
4:00:00 AMGN 194.63
4:00:00 AMGP 21.47
4:00:00 AMH 20.05
4:00:00 AMID 14.6
4:00:00 AMJ 29.08
4:00:00 AMKR 10.22
4:00:00 AMLP 11.39
4:00:00 AMMA 0.86
4:00:00 AMN 53.4
4:00:00 AMNB 37.85
4:00:00 AMOT 34.81
4:00:00 AMP 175.49
4:00:00 AMPH 19.19
4:00:00 AMRB 15.27
4:00:00 AMRN 3.77
4:00:00 AMRS 5.14
4:00:00 AMSC 5.27
4:00:00 AMSWA 12.68
4:00:00 AMT 143.44
4:00:00 AMTD 55.53
4:00:00 AMWD 136.8
4:00:00 AMX 18.64
4:00:00 AMZA 8.55
4:00:00 AMZN 1405.1
4:00:00 AN 60.57
4:00:00 ANAB 108.49
4:00:00 ANAT 127.08
4:00:00 ANCX 28.78
4:00:00 ANDA 10.35
4:00:00 ANDE 34.19
4:00:00 ANDV 109.44
4:00:00 ANDX 51.01
4:00:00 ANET 262.51
4:00:00 ANF 21.4
4:00:00 ANFI 4.23
4:00:00 ANGI 13.48
4:00:00 ANGO 16.99
4:00:00 ANH 4.98
4:00:00 ANIK 67.55
4:00:00 ANIP 67.37
4:00:00 ANSS 163.53
4:00:00 ANTH 1.73
4:00:00 ANTM 244.48
4:00:00 ANTX 59.53
4:00:00 ANY 2.33
4:00:00 AOBC 12.13
4:00:00 AOD 9.93
4:00:00 AON 142.62
4:00:00 AOS 65.33
4:00:00 AOSL 16.75
4:00:00 APA 45.1
4:00:00 APC 59.66
4:00:00 APD 166.64
4:00:00 APDN 1.51
4:00:00 APEN 6.08
4:00:00 APH 91.96
4:00:00 APHB 1.22
4:00:00 APLE 19.64
4:00:00 APLP 13.68
4:00:00 APLS 16.22
4:00:00 APO 35.48
4:00:00 APOG 45.85
4:00:00 APOP 8.52
4:00:00 APPF 43.2
4:00:00 APPN 30.25
4:00:00 APPS 2.09
4:00:00 APRI 2.51
4:00:00 APRN 3.03
4:00:00 APTI 25.24
4:00:00 APTO 2.96
4:00:00 APTS 16.38
4:00:00 APTV 94.48
4:00:00 APU 47.03
4:00:00 APVO 3.61
4:00:00 AQ 12.23
4:00:00 AQN 10.8
4:00:00 AQUA 23.8
4:00:00 AQXP 12.93
4:00:00 AR 19.64
4:00:00 ARA 18.7
4:00:00 ARAY 5.52
4:00:00 ARC 2.4
4:00:00 ARCB 36.6
4:00:00 ARCC 16.1
4:00:00 ARCH 91.94
4:00:00 ARCO 9.9
4:00:00 ARD 19.63
4:00:00 ARDM 1.53
4:00:00 ARDX 7.53
4:00:00 ARE 124.58
4:00:00 ARES-A 25.81
4:00:00 AREX 3.32
4:00:00 ARGS 2.11
4:00:00 ARGT 37.46
4:00:00 ARGX 78.05
4:00:00 ARI 18.35
4:00:00 ARII 40.04
4:00:00 ARKK 41.49
4:00:00 ARKW 50.21
4:00:00 ARLP 21.3
4:00:00 ARMK 45.55
4:00:00 ARMO 29.66
4:00:00 ARNA 35.69
4:00:00 ARNC 29.79
4:00:00 AROC 9.81
4:00:00 ARR 23.77
4:00:00 ARRS 25.17
4:00:00 ARRY 14.44
4:00:00 ARTNA 37.42
4:00:00 ARTX 3.65
4:00:00 ARW 82.93
4:00:00 ARWR 6.0
4:00:00 ASB 25.2
4:00:00 ASCMA 9.95
4:00:00 ASGN 69.83
4:00:00 ASH 70.71
4:00:00 ASHR 33.64
4:00:00 ASHX 23.2
4:00:00 ASIX 40.14
4:00:00 ASMB 48.54
4:00:00 ASML 202.64
4:00:00 ASNA 2.26
4:00:00 ASND 53.33
4:00:00 ASNS 13.9
4:00:00 ASPS 30.45
4:00:00 ASRV 4.15
4:00:00 ASTC 3.39
4:00:00 ASTE 63.03
4:00:00 ASYS 10.32
4:00:00 AT 2.22
4:00:00 ATAC 9.85
4:00:00 ATEC 3.38
4:00:00 ATH 50.62
4:00:00 ATHM 81.03
4:00:00 ATHN 128.05
4:00:00 ATHX 1.82
4:00:00 ATI 27.98
4:00:00 ATKR 23.85
4:00:00 ATLO 28.75
4:00:00 ATNI 59.31
4:00:00 ATNX 14.9
4:00:00 ATO 82.72
4:00:00 ATOS 0.59
4:00:00 ATR 87.57
4:00:00 ATRA 36.84
4:00:00 ATRC 16.49
4:00:00 ATRI 578.01
4:00:00 ATRO 45.73
4:00:00 ATRS 2.3
4:00:00 ATSG 24.87
4:00:00 ATU 25.47
4:00:00 ATUS 21.94
4:00:00 ATVI 71.49
4:00:00 ATXI 3.88
4:00:00 AU 11.15
4:00:00 AUDC 7.62
4:00:00 AUMN 0.45
4:00:00 AUO 4.84
4:00:00 AUPH 5.3
4:00:00 AUTO 8.28
4:00:00 AUY 3.5
4:00:00 AVA 51.09
4:00:00 AVAL 9.31
4:00:00 AVAV 51.55
4:00:00 AVB 167.97
4:00:00 AVDL 11.63
4:00:00 AVEO 3.03
4:00:00 AVGO 241.93
4:00:00 AVHI 17.19
4:00:00 AVID 5.4
4:00:00 AVIR 0.59
4:00:00 AVK 16.33
4:00:00 AVNW 16.85
4:00:00 AVP 2.43
4:00:00 AVT 42.92
4:00:00 AVX 18.01
4:00:00 AVXS 113.03
4:00:00 AVY 118.6
4:00:00 AWI 62.17
4:00:00 AWK 83.46
4:00:00 AWP 6.68
4:00:00 AWR 56.23
4:00:00 AXAS 2.32
4:00:00 AXDX 28.12
4:00:00 AXE 86.34
4:00:00 AXGN 27.22
4:00:00 AXL 18.08
4:00:00 AXON 2.06
4:00:00 AXP 99.84
4:00:00 AXS 50.52
4:00:00 AXSM 2.72
4:00:00 AXTA 31.39
4:00:00 AXTI 8.05
4:00:00 AY 20.99
4:00:00 AYI 161.78
4:00:00 AYR 23.97
4:00:00 AYTU 3.0
4:00:00 AYX 29.17
4:00:00 AZN 35.94
4:00:00 AZO 782.07
4:00:00 AZPN 79.09
4:00:00 AZRX 3.02
4:00:00 AZUL 28.32
4:00:00 AZZ 46.1
4:00:00 B 66.6
4:00:00 BA 336.48
4:00:00 BABA 198.09
4:00:00 BABY 31.65
4:00:00 BAC 32.03
4:00:00 BAC+A 20.09
4:00:00 BAC+B 3.43
4:00:00 BAC-I 25.56
4:00:00 BAC-L 1262.89
4:00:00 BAC-W 26.2
4:00:00 BAH 39.5
4:00:00 BAK 31.44
4:00:00 BAL 51.92
4:00:00 BAM 41.2
4:00:00 BANC-E 25.31
4:00:00 BANF 55.55
4:00:00 BANR 54.56
4:00:00 BAP 235.81
4:00:00 BAS 19.31
4:00:00 BATRA 24.17
4:00:00 BATRK 24.13
4:00:00 BAX 71.56
4:00:00 BB 12.76
4:00:00 BBBY 22.5
4:00:00 BBD 12.43
4:00:00 BBG 4.95
4:00:00 BBL 44.49
