output/05.txt
time symbol vwap
5:00:00 A 73.38
5:00:00 AA 53.2
5:00:00 AABA 78.3
5:00:00 AAC 9.24
5:00:00 AAL 52.68
5:00:00 AAN 41.86
5:00:00 AAOI 32.62
5:00:00 AAP 120.43
5:00:00 AAPL 166.77
5:00:00 AAT 34.89
5:00:00 AAWW 58.15
5:00:00 AAXJ 81.12
5:00:00 AAXN 27.5
5:00:00 ABAC 2.85
5:00:00 ABAX 75.2
5:00:00 ABB 28.01
5:00:00 ABBV 118.3
5:00:00 ABC 101.13
5:00:00 ABCB 55.04
5:00:00 ABCD 7.07
5:00:00 ABEO 15.53
5:00:00 ABEOW 10.66
5:00:00 ABEV 6.82
5:00:00 ABG 74.13
5:00:00 ABIL 0.46
5:00:00 ABIO 1.74
5:00:00 ABLX 54.28
5:00:00 ABM 38.34
5:00:00 ABMD 235.28
5:00:00 ABR 8.33
5:00:00 ABT 62.93
5:00:00 ABTX 40.64
5:00:00 ABUS 5.12
5:00:00 ABX 14.41
5:00:00 ACAD 31.39
5:00:00 ACBI 17.39
5:00:00 ACC 38.28
5:00:00 ACCO 12.0
5:00:00 ACER 19.21
5:00:00 ACET 11.54
5:00:00 ACFC 10.57
5:00:00 ACGL 91.5
5:00:00 ACGLO 24.5
5:00:00 ACGLP 23.25
5:00:00 ACH 17.54
5:00:00 ACHC 34.66
5:00:00 ACHN 2.78
5:00:00 ACIA 35.26
5:00:00 ACIU 13.3
5:00:00 ACIW 23.13
5:00:00 ACLS 26.2
5:00:00 ACM 39.03
5:00:00 ACMR 5.4
5:00:00 ACN 159.71
5:00:00 ACOR 26.76
5:00:00 ACRS 23.02
5:00:00 ACRX 1.98
5:00:00 ACT 26.78
5:00:00 ACTA 15.58
5:00:00 ACU 23.8
5:00:00 ACV 22.35
5:00:00 ACWI 76.15
5:00:00 ACWV 87.06
5:00:00 ACWX 52.72
5:00:00 ACXM 27.51
5:00:00 ADAP 9.05
5:00:00 ADBE 195.96
5:00:00 ADC 47.96
5:00:00 ADES 8.16
5:00:00 ADI 91.96
5:00:00 ADM 42.62
5:00:00 ADMA 3.82
5:00:00 ADMP 3.68
5:00:00 ADMS 38.7
5:00:00 ADNT 65.33
5:00:00 ADOM 1.64
5:00:00 ADP 120.04
5:00:00 ADRE 47.28
5:00:00 ADRO 6.82
5:00:00 ADS 256.41
5:00:00 ADSK 114.8
5:00:00 ADSW 24.08
5:00:00 ADT 12.17
5:00:00 ADTN 16.1
5:00:00 ADUS 36.1
5:00:00 ADVM 7.47
5:00:00 ADXS 3.02
5:00:00 AE 45.98
5:00:00 AEB 23.97
5:00:00 AED 25.59
5:00:00 AEE 55.95
5:00:00 AEG 6.88
5:00:00 AEGN 25.17
5:00:00 AEH 25.62
5:00:00 AEHR 2.64
5:00:00 AEIS 73.94
5:00:00 AEK 26.28
5:00:00 AEL 34.56
5:00:00 AEM 47.54
5:00:00 AEMD 1.58
5:00:00 AEO 18.32
5:00:00 AEP 68.42
5:00:00 AER 54.38
5:00:00 AERI 56.77
5:00:00 AES 11.66
5:00:00 AET 188.27
5:00:00 AEZS 2.27
5:00:00 AFAM 58.06
5:00:00 AFB 12.91
5:00:00 AFG 113.76
5:00:00 AFH 20.25
5:00:00 AFL 88.92
5:00:00 AFMD 1.35
5:00:00 AFSI 12.95
5:00:00 AFSI-F 18.58
5:00:00 AFST 24.48
5:00:00 AG 6.33
5:00:00 AGCO 72.18
5:00:00 AGD 11.36
5:00:00 AGEN 3.67
5:00:00 AGFS 7.41
5:00:00 AGG 108.07
5:00:00 AGI 6.04
5:00:00 AGII 62.5
5:00:00 AGIIL 25.33
5:00:00 AGIO 79.7
5:00:00 AGLE 6.45
5:00:00 AGM 80.64
5:00:00 AGN 184.83
5:00:00 AGNC 19.07
5:00:00 AGNCB 25.66
5:00:00 AGNCN 25.38
5:00:00 AGND 44.02
5:00:00 AGO 36.04
5:00:00 AGO-F 24.48
5:00:00 AGR 48.09
5:00:00 AGRO 9.86
5:00:00 AGRX 3.33
5:00:00 AGS 18.38
5:00:00 AGTC 5.03
5:00:00 AGX 43.74
5:00:00 AGYS 12.19
5:00:00 AHGP 28.78
5:00:00 AHH 14.44
5:00:00 AHL 37.59
5:00:00 AHL-D 24.26
5:00:00 AHP 9.32
5:00:00 AHT 6.47
5:00:00 AI 10.9
5:00:00 AIA 70.94
5:00:00 AIF 15.56
5:00:00 AIG 63.98
5:00:00 AIG+ 22.02
5:00:00 AIMT 36.02
5:00:00 AINV 5.77
5:00:00 AIRG 10.12
5:00:00 AIT 73.55
5:00:00 AIV 41.09
5:00:00 AIZ 93.54
5:00:00 AJG 69.58
5:00:00 AJRD 27.62
5:00:00 AJX 13.47
5:00:00 AKAM 66.95
5:00:00 AKAO 12.38
5:00:00 AKBA 15.36
5:00:00 AKCA 22.73
5:00:00 AKER 0.25
5:00:00 AKG 0.93
5:00:00 AKO.B 28.73
5:00:00 AKR 24.71
5:00:00 AKRX 32.22
5:00:00 AKS 5.81
5:00:00 AKTS 5.99
5:00:00 AKTX 3.14
5:00:00 AL 49.11
5:00:00 ALB 112.91
5:00:00 ALBO 37.35
5:00:00 ALDR 14.5
5:00:00 ALDW 16.68
5:00:00 ALDX 7.53
5:00:00 ALE 71.9
5:00:00 ALEX 27.24
5:00:00 ALG 116.98
5:00:00 ALGN 262.97
5:00:00 ALGT 160.72
5:00:00 ALIM 1.18
5:00:00 ALK 64.65
5:00:00 ALKS 59.14
5:00:00 ALL 98.81
5:00:00 ALLE 85.95
5:00:00 ALLY 30.21
5:00:00 ALLY-A 25.99
5:00:00 ALN 0.23
5:00:00 ALNA 8.97
5:00:00 ALNY 131.16
5:00:00 ALO 3.25
5:00:00 ALOG 84.14
5:00:00 ALP-Q 24.96
5:00:00 ALPN 11.2
5:00:00 ALQA 2.05
5:00:00 ALRM 37.74
5:00:00 ALSK 2.26
5:00:00 ALSN 43.71
5:00:00 ALT 1.82
5:00:00 ALTR 25.34
5:00:00 ALV 148.0
5:00:00 ALXN 124.17
5:00:00 AM 30.81
5:00:00 AMAG 14.62
5:00:00 AMAT 53.51
5:00:00 AMBA 50.37
5:00:00 AMBC 16.45
5:00:00 AMC 12.59
5:00:00 AMCN 1.19
5:00:00 AMCX 53.51
5:00:00 AMD 13.13
5:00:00 AME 76.83
5:00:00 AMED 54.24
5:00:00 AMEH 19.7
5:00:00 AMG 206.29
5:00:00 AMGN 193.14
5:00:00 AMGP 21.45
5:00:00 AMH 20.04
5:00:00 AMJ 29.1
5:00:00 AMKR 10.24
5:00:00 AMLP 11.41
5:00:00 AMMA 0.84
5:00:00 AMN 53.72
5:00:00 AMNB 37.79
5:00:00 AMOT 35.01
5:00:00 AMP 174.2
5:00:00 AMPE 2.7
5:00:00 AMPH 19.21
5:00:00 AMRK 13.65
5:00:00 AMRN 3.75
5:00:00 AMRS 5.15
5:00:00 AMSC 5.19
5:00:00 AMSF 61.33
5:00:00 AMSWA 12.71
5:00:00 AMT 144.36
5:00:00 AMTD 55.69
5:00:00 AMWD 135.79
5:00:00 AMX 18.48
5:00:00 AMZA 8.57
5:00:00 AMZN 1410.3
5:00:00 AN 60.43
5:00:00 ANAB 108.07
5:00:00 ANAT 127.76
5:00:00 ANCX 28.98
5:00:00 ANDE 34.37
5:00:00 ANDV 108.84
5:00:00 ANDX 51.04
5:00:00 ANET 271.76
5:00:00 ANF 21.42
5:00:00 ANFI 4.08
5:00:00 ANGI 13.44
5:00:00 ANGL 30.19
5:00:00 ANGO 17.17
5:00:00 ANH 4.98
5:00:00 ANIK 67.77
5:00:00 ANIP 68.69
5:00:00 ANSS 161.05
5:00:00 ANTH 1.71
5:00:00 ANTM 243.73
5:00:00 ANTX 59.3
5:00:00 ANY 2.37
5:00:00 AOA 56.07
5:00:00 AOBC 12.01
5:00:00 AOD 9.91
5:00:00 AON 141.88
5:00:00 AOS 65.82
5:00:00 AOSL 16.72
5:00:00 APA 44.77
5:00:00 APAM 40.57
5:00:00 APC 59.71
5:00:00 APD 166.37
5:00:00 APEI 25.45
5:00:00 APH 92.29
5:00:00 APHB 1.23
5:00:00 APLE 19.6
5:00:00 APLP 13.81
5:00:00 APLS 16.12
5:00:00 APO 35.48
5:00:00 APOG 45.94
5:00:00 APOP 8.47
5:00:00 APPF 43.5
5:00:00 APPN 29.89
5:00:00 APPS 2.06
5:00:00 APRI 2.42
5:00:00 APRN 3.06
5:00:00 APTI 25.51
5:00:00 APTO 2.97
5:00:00 APTS 16.4
5:00:00 APTV 94.49
5:00:00 APU 47.16
5:00:00 APVO 3.5
5:00:00 AQ 12.02
5:00:00 AQB 2.65
5:00:00 AQMS 1.83
5:00:00 AQUA 23.5
5:00:00 AQXP 12.94
5:00:00 AR 19.34
5:00:00 ARA 18.63
5:00:00 ARAY 5.61
5:00:00 ARC 2.38
5:00:00 ARCB 36.63
5:00:00 ARCC 16.02
5:00:00 ARCH 91.27
5:00:00 ARCO 9.87
5:00:00 ARCT 8.63
5:00:00 ARD 19.9
5:00:00 ARDM 1.46
5:00:00 ARDX 7.55
5:00:00 ARE 124.5
5:00:00 ARES 24.06
5:00:00 AREX 3.31
5:00:00 ARGS 3.19
5:00:00 ARGT 37.34
5:00:00 ARGX 79.12
5:00:00 ARI 18.35
5:00:00 ARII 39.81
5:00:00 ARKG 28.76
5:00:00 ARKK 41.51
5:00:00 ARKQ 35.75
5:00:00 ARKW 50.36
5:00:00 ARLP 20.69
5:00:00 ARLZ 1.75
5:00:00 ARMK 45.59
5:00:00 ARMO 29.87
5:00:00 ARNA 36.22
5:00:00 ARNC 29.53
5:00:00 AROC 9.87
5:00:00 AROW 33.69
5:00:00 ARR 23.83
5:00:00 ARRS 25.2
5:00:00 ARRY 14.23
5:00:00 ARTNA 37.58
5:00:00 ARTW 3.1
5:00:00 ARTX 3.62
5:00:00 ARW 82.89
5:00:00 ARWR 6.05
5:00:00 ASA 11.55
5:00:00 ASB 25.05
5:00:00 ASC 7.08
5:00:00 ASCMA 10.03
5:00:00 ASGN 69.28
5:00:00 ASH 71.85
5:00:00 ASHR 33.61
5:00:00 ASIX 40.16
5:00:00 ASMB 49.08
5:00:00 ASML 202.3
5:00:00 ASNA 2.21
5:00:00 ASND 53.24
5:00:00 ASNS 13.9
5:00:00 ASPS 30.49
5:00:00 ASR 193.7
5:00:00 ASTC 3.43
5:00:00 ASTE 63.07
5:00:00 ASUR 15.12
5:00:00 ASYS 10.01
5:00:00 ATEC 3.36
5:00:00 ATEN 6.98
5:00:00 ATGE 45.97
5:00:00 ATH 50.78
5:00:00 ATHM 81.01
5:00:00 ATHN 128.04
5:00:00 ATHX 1.79
5:00:00 ATI 27.89
5:00:00 ATKR 23.97
5:00:00 ATLO 28.73
5:00:00 ATNI 59.09
5:00:00 ATNM 0.72
5:00:00 ATNX 14.95
5:00:00 ATO 82.79
5:00:00 ATOM 4.4
5:00:00 ATOS 0.52
5:00:00 ATR 87.58
5:00:00 ATRA 37.88
5:00:00 ATRC 16.55
5:00:00 ATRI 566.2
5:00:00 ATRO 45.86
5:00:00 ATRS 2.27
5:00:00 ATSG 25.07
5:00:00 ATTO 9.8
5:00:00 ATU 25.42
5:00:00 ATUS 21.68
5:00:00 ATVI 71.12
5:00:00 ATXI 3.83
5:00:00 AU 11.12
5:00:00 AUDC 7.65
5:00:00 AUO 4.81
5:00:00 AUPH 5.41
5:00:00 AUTO 8.24
5:00:00 AUY 3.43
5:00:00 AVA 51.04
5:00:00 AVAL 9.2
5:00:00 AVAV 51.02
5:00:00 AVB 167.33
5:00:00 AVD 21.36
5:00:00 AVDL 11.46
5:00:00 AVEO 3.0
5:00:00 AVGO 243.37
5:00:00 AVGR 0.18
5:00:00 AVHI 17.34
5:00:00 AVIR 0.62
5:00:00 AVNW 17.04
5:00:00 AVP 2.42
5:00:00 AVT 42.83
5:00:00 AVX 17.99
5:00:00 AVXL 2.89
5:00:00 AVXS 118.82
5:00:00 AVY 117.98
5:00:00 AVYA 20.17
5:00:00 AWF 12.44
5:00:00 AWI 62.82
5:00:00 AWK 83.5
5:00:00 AWP 6.64
5:00:00 AWR 56.0
5:00:00 AXAS 2.32
5:00:00 AXDX 28.39
5:00:00 AXE 87.55
5:00:00 AXGN 27.28
5:00:00 AXL 17.79
5:00:00 AXON 2.04
5:00:00 AXP 99.9
5:00:00 AXS 50.62
5:00:00 AXS-D 24.69
5:00:00 AXSM 2.78
5:00:00 AXTA 30.89
5:00:00 AXTI 8.2
5:00:00 AXU 1.54
5:00:00 AY 20.96
5:00:00 AYI 160.75
5:00:00 AYR 23.85
